<mujoco model="ur3">
  <compiler angle="radian" meshdir="ur_description/meshes/ur3/collision/"/>
  <actuator>
    <motor gear="10000" joint="shoulder_pan_joint" name="shoulder_pan_joint" ctrlrange="-500 500" ctrllimited="true"/>
    <motor gear="10000" joint="shoulder_lift_joint" name="shoulder_lift_joint" ctrlrange="-500 500" ctrllimited="true"/>
    <motor gear="10000" joint="elbow_joint" name="elbow_joint" ctrlrange="-500 500" ctrllimited="true"/>
    <motor gear="10000" joint="wrist_1_joint" name="wrist_1_joint" ctrlrange="-500 500" ctrllimited="true"/>
    <motor gear="10000" joint="wrist_2_joint" name="wrist_2_joint" ctrlrange="-500 500" ctrllimited="true"/>
    <motor gear="10000" joint="wrist_3_joint" name="wrist_3_joint" ctrlrange="-500 500" ctrllimited="true"/>
  </actuator>
  <sensor>
    <jointpos joint="shoulder_pan_joint"/>
    <jointpos joint="shoulder_lift_joint"/>
    <jointpos joint="elbow_joint"/>
    <jointpos joint="wrist_1_joint"/>
    <jointpos joint="wrist_2_joint"/>
    <jointpos joint="wrist_3_joint"/>
  </sensor>

  <asset>
    <mesh name="base" file="base.stl"/>
    <mesh name="shoulder" file="shoulder.stl"/>
    <mesh name="upperarm" file="upperarm.stl"/>
    <mesh name="forearm" file="forearm.stl"/>
    <mesh name="wrist1" file="wrist1.stl"/>
    <mesh name="wrist2" file="wrist2.stl"/>
    <mesh name="wrist3" file="wrist3.stl"/>
  </asset>
  <worldbody>
    <body name="base_link">
      <inertial pos="0 0 0" quat="0.5 0.5 -0.5 0.5" mass="2" diaginertia="0.005625 0.00305317 0.00305317"/>
      <geom type="mesh" contype="0" conaffinity="0" group="1" density="0" rgba="0.7 0.7 0.7 1" mesh="base"/>
      <geom type="mesh" rgba="0.7 0.7 0.7 1" mesh="base"/>
      <body name="shoulder_link" pos="0 0 0.1519">
        <inertial pos="0 0 0" quat="0.5 0.5 -0.5 0.5" mass="2" diaginertia="0.0118674 0.00809316 0.00809316"/>
        <joint name="shoulder_pan_joint" pos="0 0 0" axis="0 0 1" range="-6.28319 6.28319" actuatorfrcrange="-330 330"/>
        <geom type="mesh" contype="0" conaffinity="0" group="1" density="0" rgba="0.7 0.7 0.7 1" mesh="shoulder"/>
        <geom type="mesh" rgba="0.7 0.7 0.7 1" mesh="shoulder"/>
        <body name="upper_arm_link" pos="0 0.1198 0" quat="0.707107 0 0.707107 0">
          <inertial pos="0 0 0.121825" quat="0.707107 0 0 0.707107" mass="3.42" diaginertia="0.0279709 0.0217285 0.00961875"/>
          <joint name="shoulder_lift_joint" pos="0 0 0" axis="0 1 0" range="-6.28319 6.28319" actuatorfrcrange="-330 330"/>
          <geom type="mesh" contype="0" conaffinity="0" group="1" density="0" rgba="0.7 0.7 0.7 1" mesh="upperarm"/>
          <geom type="mesh" rgba="0.7 0.7 0.7 1" mesh="upperarm"/>
          <body name="forearm_link" pos="0 -0.0925 0.24365">
            <inertial pos="0 0 0.106625" quat="0.707107 0 0 0.707107" mass="1.26" diaginertia="0.00762659 0.00762659 0.00762659"/>
            <joint name="elbow_joint" pos="0 0 0" axis="0 1 0" range="-3.14159 3.14159" actuatorfrcrange="-150 150"/>
            <geom type="mesh" contype="0" conaffinity="0" group="1" density="0" rgba="0.7 0.7 0.7 1" mesh="forearm"/>
            <geom type="mesh" rgba="0.7 0.7 0.7 1" mesh="forearm"/>
            <body name="wrist_1_link" pos="0 0 0.21325" quat="0.707107 0 0.707107 0">
              <inertial pos="0 0 0" quat="0.5 0.5 0.5 0.5" mass="0.8" diaginertia="0.0042208 0.0042208 0.0042208"/>
              <joint name="wrist_1_joint" pos="0 0 0" axis="0 1 0" range="-6.28319 6.28319" actuatorfrcrange="-54 54"/>
              <geom type="mesh" contype="0" conaffinity="0" group="1" density="0" rgba="0.7 0.7 0.7 1" mesh="wrist1"/>
              <geom type="mesh" rgba="0.7 0.7 0.7 1" mesh="wrist1"/>
              <body name="wrist_2_link" pos="0 0.08505 0">
                <inertial pos="0 0 0" quat="0.5 0.5 -0.5 0.5" mass="0.8" diaginertia="0.0042208 0.0042208 0.0042208"/>
                <joint name="wrist_2_joint" pos="0 0 0" axis="0 0 1" range="-6.28319 6.28319" actuatorfrcrange="-54 54"/>
                <geom type="mesh" contype="0" conaffinity="0" group="1" density="0" rgba="0.7 0.7 0.7 1" mesh="wrist2"/>
                <geom type="mesh" rgba="0.7 0.7 0.7 1" mesh="wrist2"/>
                <body name="wrist_3_link" pos="0 0 0.08535">
                  <inertial pos="0 0 0" quat="0.5 0.5 0.5 0.5" mass="0.35" diaginertia="0.00301705 0.00301705 0.00301705"/>
                  <joint name="wrist_3_joint" pos="0 0 0" axis="0 1 0" range="-6.28319 6.28319" actuatorfrcrange="-54 54"/>
                  <geom type="mesh" contype="0" conaffinity="0" group="1" density="0" rgba="0.7 0.7 0.7 1" mesh="wrist3"/>
                  <geom type="mesh" rgba="0.7 0.7 0.7 1" mesh="wrist3"/>
                  <body name="ee_link" pos="0 0.0819 0" quat="0.707107 0 0 0.707107">
                    <geom size="0.005 0.005 0.005" pos="-0.01 0 0" type="box"/>
                  </body>
                  <body name="tool0" pos="0 0.0819 0" quat="0.707107 -0.707107 0 0"/>
                </body>
              </body>
            </body>
          </body>
        </body>
      </body>
      <body name="base" quat="0 0 0 -1"/>
    </body>
  </worldbody>

</mujoco>
